2022-03-16 13:45:15,892 -  nornir.core -     INFO -        run() - Running task 'netmiko_send_command' with args {'command_string': 'show interface status'} on 3 hosts
2022-03-16 13:45:20,984 - nornir.core.task -    ERROR -      start() - Host 'arista2': task 'netmiko_send_command' failed with traceback:
Traceback (most recent call last):
  File "/Users/matt.miller/Documents/git/practice/Kirk_Byers_Nornir_Automation/env/lib/python3.8/site-packages/netmiko/base_connection.py", line 935, in establish_connection
    self.remote_conn_pre.connect(**ssh_connect_params)
  File "/Users/matt.miller/Documents/git/practice/Kirk_Byers_Nornir_Automation/env/lib/python3.8/site-packages/paramiko/client.py", line 349, in connect
    retry_on_signal(lambda: sock.connect(addr))
  File "/Users/matt.miller/Documents/git/practice/Kirk_Byers_Nornir_Automation/env/lib/python3.8/site-packages/paramiko/util.py", line 283, in retry_on_signal
    return function()
  File "/Users/matt.miller/Documents/git/practice/Kirk_Byers_Nornir_Automation/env/lib/python3.8/site-packages/paramiko/client.py", line 349, in <lambda>
    retry_on_signal(lambda: sock.connect(addr))
socket.timeout: timed out

During handling of the above exception, another exception occurred:

Traceback (most recent call last):
  File "/Users/matt.miller/Documents/git/practice/Kirk_Byers_Nornir_Automation/env/lib/python3.8/site-packages/nornir/core/task.py", line 99, in start
    r = self.task(self, **self.params)
  File "/Users/matt.miller/Documents/git/practice/Kirk_Byers_Nornir_Automation/env/lib/python3.8/site-packages/nornir_netmiko/tasks/netmiko_send_command.py", line 26, in netmiko_send_command
    net_connect = task.host.get_connection(CONNECTION_NAME, task.nornir.config)
  File "/Users/matt.miller/Documents/git/practice/Kirk_Byers_Nornir_Automation/env/lib/python3.8/site-packages/nornir/core/inventory.py", line 494, in get_connection
    self.open_connection(
  File "/Users/matt.miller/Documents/git/practice/Kirk_Byers_Nornir_Automation/env/lib/python3.8/site-packages/nornir/core/inventory.py", line 546, in open_connection
    conn_obj.open(
  File "/Users/matt.miller/Documents/git/practice/Kirk_Byers_Nornir_Automation/env/lib/python3.8/site-packages/nornir_netmiko/connections/netmiko.py", line 59, in open
    connection = ConnectHandler(**parameters)
  File "/Users/matt.miller/Documents/git/practice/Kirk_Byers_Nornir_Automation/env/lib/python3.8/site-packages/netmiko/ssh_dispatcher.py", line 326, in ConnectHandler
    return ConnectionClass(*args, **kwargs)
  File "/Users/matt.miller/Documents/git/practice/Kirk_Byers_Nornir_Automation/env/lib/python3.8/site-packages/netmiko/cisco/cisco_ios.py", line 17, in __init__
    return super().__init__(*args, **kwargs)
  File "/Users/matt.miller/Documents/git/practice/Kirk_Byers_Nornir_Automation/env/lib/python3.8/site-packages/netmiko/base_connection.py", line 350, in __init__
    self._open()
  File "/Users/matt.miller/Documents/git/practice/Kirk_Byers_Nornir_Automation/env/lib/python3.8/site-packages/netmiko/base_connection.py", line 355, in _open
    self.establish_connection()
  File "/Users/matt.miller/Documents/git/practice/Kirk_Byers_Nornir_Automation/env/lib/python3.8/site-packages/netmiko/base_connection.py", line 957, in establish_connection
    raise NetmikoTimeoutException(msg)
netmiko.ssh_exception.NetmikoTimeoutException: TCP connection to device failed.

Common causes of this problem are:
1. Incorrect hostname or IP address.
2. Wrong TCP port.
3. Intermediate firewall blocking access.

Device settings: cisco_ios arista2.lasthop.io:22



2022-03-16 13:45:20,985 - nornir.core.task -    ERROR -      start() - Host 'arista3': task 'netmiko_send_command' failed with traceback:
Traceback (most recent call last):
  File "/Users/matt.miller/Documents/git/practice/Kirk_Byers_Nornir_Automation/env/lib/python3.8/site-packages/netmiko/base_connection.py", line 935, in establish_connection
    self.remote_conn_pre.connect(**ssh_connect_params)
  File "/Users/matt.miller/Documents/git/practice/Kirk_Byers_Nornir_Automation/env/lib/python3.8/site-packages/paramiko/client.py", line 349, in connect
    retry_on_signal(lambda: sock.connect(addr))
  File "/Users/matt.miller/Documents/git/practice/Kirk_Byers_Nornir_Automation/env/lib/python3.8/site-packages/paramiko/util.py", line 283, in retry_on_signal
    return function()
  File "/Users/matt.miller/Documents/git/practice/Kirk_Byers_Nornir_Automation/env/lib/python3.8/site-packages/paramiko/client.py", line 349, in <lambda>
    retry_on_signal(lambda: sock.connect(addr))
socket.timeout: timed out

During handling of the above exception, another exception occurred:

Traceback (most recent call last):
  File "/Users/matt.miller/Documents/git/practice/Kirk_Byers_Nornir_Automation/env/lib/python3.8/site-packages/nornir/core/task.py", line 99, in start
    r = self.task(self, **self.params)
  File "/Users/matt.miller/Documents/git/practice/Kirk_Byers_Nornir_Automation/env/lib/python3.8/site-packages/nornir_netmiko/tasks/netmiko_send_command.py", line 26, in netmiko_send_command
    net_connect = task.host.get_connection(CONNECTION_NAME, task.nornir.config)
  File "/Users/matt.miller/Documents/git/practice/Kirk_Byers_Nornir_Automation/env/lib/python3.8/site-packages/nornir/core/inventory.py", line 494, in get_connection
    self.open_connection(
  File "/Users/matt.miller/Documents/git/practice/Kirk_Byers_Nornir_Automation/env/lib/python3.8/site-packages/nornir/core/inventory.py", line 546, in open_connection
    conn_obj.open(
  File "/Users/matt.miller/Documents/git/practice/Kirk_Byers_Nornir_Automation/env/lib/python3.8/site-packages/nornir_netmiko/connections/netmiko.py", line 59, in open
    connection = ConnectHandler(**parameters)
  File "/Users/matt.miller/Documents/git/practice/Kirk_Byers_Nornir_Automation/env/lib/python3.8/site-packages/netmiko/ssh_dispatcher.py", line 326, in ConnectHandler
    return ConnectionClass(*args, **kwargs)
  File "/Users/matt.miller/Documents/git/practice/Kirk_Byers_Nornir_Automation/env/lib/python3.8/site-packages/netmiko/cisco/cisco_ios.py", line 17, in __init__
    return super().__init__(*args, **kwargs)
  File "/Users/matt.miller/Documents/git/practice/Kirk_Byers_Nornir_Automation/env/lib/python3.8/site-packages/netmiko/base_connection.py", line 350, in __init__
    self._open()
  File "/Users/matt.miller/Documents/git/practice/Kirk_Byers_Nornir_Automation/env/lib/python3.8/site-packages/netmiko/base_connection.py", line 355, in _open
    self.establish_connection()
  File "/Users/matt.miller/Documents/git/practice/Kirk_Byers_Nornir_Automation/env/lib/python3.8/site-packages/netmiko/base_connection.py", line 957, in establish_connection
    raise NetmikoTimeoutException(msg)
netmiko.ssh_exception.NetmikoTimeoutException: TCP connection to device failed.

Common causes of this problem are:
1. Incorrect hostname or IP address.
2. Wrong TCP port.
3. Intermediate firewall blocking access.

Device settings: cisco_ios arista3.lasthop.io:8443



2022-03-16 13:45:20,985 - nornir.core.task -    ERROR -      start() - Host 'arista1': task 'netmiko_send_command' failed with traceback:
Traceback (most recent call last):
  File "/Users/matt.miller/Documents/git/practice/Kirk_Byers_Nornir_Automation/env/lib/python3.8/site-packages/netmiko/base_connection.py", line 935, in establish_connection
    self.remote_conn_pre.connect(**ssh_connect_params)
  File "/Users/matt.miller/Documents/git/practice/Kirk_Byers_Nornir_Automation/env/lib/python3.8/site-packages/paramiko/client.py", line 349, in connect
    retry_on_signal(lambda: sock.connect(addr))
  File "/Users/matt.miller/Documents/git/practice/Kirk_Byers_Nornir_Automation/env/lib/python3.8/site-packages/paramiko/util.py", line 283, in retry_on_signal
    return function()
  File "/Users/matt.miller/Documents/git/practice/Kirk_Byers_Nornir_Automation/env/lib/python3.8/site-packages/paramiko/client.py", line 349, in <lambda>
    retry_on_signal(lambda: sock.connect(addr))
socket.timeout: timed out

During handling of the above exception, another exception occurred:

Traceback (most recent call last):
  File "/Users/matt.miller/Documents/git/practice/Kirk_Byers_Nornir_Automation/env/lib/python3.8/site-packages/nornir/core/task.py", line 99, in start
    r = self.task(self, **self.params)
  File "/Users/matt.miller/Documents/git/practice/Kirk_Byers_Nornir_Automation/env/lib/python3.8/site-packages/nornir_netmiko/tasks/netmiko_send_command.py", line 26, in netmiko_send_command
    net_connect = task.host.get_connection(CONNECTION_NAME, task.nornir.config)
  File "/Users/matt.miller/Documents/git/practice/Kirk_Byers_Nornir_Automation/env/lib/python3.8/site-packages/nornir/core/inventory.py", line 494, in get_connection
    self.open_connection(
  File "/Users/matt.miller/Documents/git/practice/Kirk_Byers_Nornir_Automation/env/lib/python3.8/site-packages/nornir/core/inventory.py", line 546, in open_connection
    conn_obj.open(
  File "/Users/matt.miller/Documents/git/practice/Kirk_Byers_Nornir_Automation/env/lib/python3.8/site-packages/nornir_netmiko/connections/netmiko.py", line 59, in open
    connection = ConnectHandler(**parameters)
  File "/Users/matt.miller/Documents/git/practice/Kirk_Byers_Nornir_Automation/env/lib/python3.8/site-packages/netmiko/ssh_dispatcher.py", line 326, in ConnectHandler
    return ConnectionClass(*args, **kwargs)
  File "/Users/matt.miller/Documents/git/practice/Kirk_Byers_Nornir_Automation/env/lib/python3.8/site-packages/netmiko/cisco/cisco_ios.py", line 17, in __init__
    return super().__init__(*args, **kwargs)
  File "/Users/matt.miller/Documents/git/practice/Kirk_Byers_Nornir_Automation/env/lib/python3.8/site-packages/netmiko/base_connection.py", line 350, in __init__
    self._open()
  File "/Users/matt.miller/Documents/git/practice/Kirk_Byers_Nornir_Automation/env/lib/python3.8/site-packages/netmiko/base_connection.py", line 355, in _open
    self.establish_connection()
  File "/Users/matt.miller/Documents/git/practice/Kirk_Byers_Nornir_Automation/env/lib/python3.8/site-packages/netmiko/base_connection.py", line 957, in establish_connection
    raise NetmikoTimeoutException(msg)
netmiko.ssh_exception.NetmikoTimeoutException: TCP connection to device failed.

Common causes of this problem are:
1. Incorrect hostname or IP address.
2. Wrong TCP port.
3. Intermediate firewall blocking access.

Device settings: cisco_ios arista1.lasthop.io:8443



